**1.http状态码如下：**

## 1xx：信息提示

这类状态代[码表](https://so.csdn.net/so/search?q=码表&spm=1001.2101.3001.7020)示临时的响应。客户端在收到常规响应之前，应准备接收一个或多个 1xx 响应。

| HTTP 状态码 | 说明       |
| :---------- | :--------- |
| 100         | 继续。     |
| 101         | 切换协议。 |

2xx：成功
这类状态代码表明服务器成功地接受了客户端请求。

HTTP 状态码	说明
200	确定。客户端请求已成功。
201	已创建。
202	已接受。
203	非权威性信息。
204	无内容。
205	重置内容。
206	部分内容。表明已部分下载了一个文件。可以续传损坏的下载，或者将下载拆分为多个并发的流。
207	多状态（WebDAV）。此消息之前应该还有一条 XML 消息，其中可能包含几个单独的响应代码，具体取决于发出了多少个子请求。

3xx：重定向
客户端浏览器必须采取更多操作来实现请求。例如，浏览器可能不得不请求服务器上的不同页面，或通过代理服务器重复该请求。

HTTP 状态码	说明
301	已永久移动。此请求和之后所有的请求都应该转到指定的 URI。
302	对象已移动。对于基于表单的身份验证，此消息通常表示为“对象已移动”。请求的资源临时驻留在不同的 URI。由于重定向有时可能会改变，客户端将来在请求时应该继续使用 RequestURI。只有在 CacheControl 或 Expires 标题字段中指示，此响应才能够缓存。
304	未修改。客户端请求的文档已在其缓存中，文档自缓存以来尚未被修改过。客户端使用文档的缓存副本，而不从服务器下载文档。
307	临时重定向。
————————————————
版权声明：本文为CSDN博主「超级字节码」的原创文章，遵循CC 4.0 BY-SA版权协议，转载请附上原文出处链接及本声明。
原文链接：https://blog.csdn.net/dgxin_605/article/details/109896967

4xx：客户端错误
发生错误，客户端似乎有问题。例如，客户端请求不存在的页面，客户端未提供有效的身份验证信息。

HTTP 状态码	说明
400	错误的请求。
401	访问被拒绝。IIS 定义了几个不同的401错误，用于指示更为具体的错误原因。这些具体的错误代码在浏览器中显示，但不在 IIS 日志中显示。详见 401状态码。
403	服务器拒绝请求。可以理解为没有权限访问此网站，服务器能够收到请求但拒绝提供服务。IIS 定义了几个不同的403错误，用于指示更为具体的错误原因，详见 403状态码。
404	服务器找不到请求的网页。例如，访问网站中不存在的页面，或者原有页面被移走或删除，则可能会出现该状态码。IIS 定义了几个不同的404错误，用于指示更为具体的错误原因，详见 404状态码。
405	用来访问本页面的 HTTP 谓词不被允许（方法不被允许）。当客户端向运行 IIS 的服务器发送一个 HTTP 请求，并且该请求包含服务器无法识别的 HTTP 动词时，就会发生此错误。若要解决此问题，请确保客户端的请求使用与 HTTP rfc 兼容的 HTTP 动词。
406	客户端浏览器不接受所请求页面的 MIME 类型。
407	要求进行代理身份验证。
412	前提条件失败。
413	请求实体太大。
414	请求 URI 太长。
415	不支持的媒体类型。
416	无法满足请求的范围。
417	执行失败。
423	锁定的错误。

401 状态码
HTTP 状态码	说明
401.1	用户名或密码无效导致登录失败。
401.2	服务器配置导致登录失败。
401.3	由于 ACL 对资源的限制而未获得授权。表示存在 NTFS 权限问题。即使您对试图访问的文件具备相应的权限，也可能发生此错误。例如，如果 IUSR 帐户无权访问 C:WinntSystem32Inetsrv 目录，您会看到这个错误。
401.4	筛选器授权失败。
401.5	ISAPI/CGI 应用程序授权失败。
401.7	由 Web 服务器上的 URL 验证策略拒绝访问。这个错误代码为 IIS 6.0 所专用。

403 状态码
HTTP 状态码	说明
403.1	执行访问被禁止。可能原因：
您没有足够的执行许可。例如，如果试图访问的 ASP 页所在的目录权限设为 “无”，或者，试图执行的 CGI 脚本所在的目录权限为 “只允许脚本”，将出现此错误消息。若要修改执行权限，请在 Microsoft 管理控制台（MMC）中右击目录，然后依次单击 “属性” 和 “目录” 选项卡，确保为试图访问的内容设置适当的执行权限。
您没有将试图执行的文件类型的脚本映射设置为识别所使用的谓词（例如，GET 或 POST）。若要验证这一点，请在 Microsoft 管理控制台中右键单击目录，依次单击 “属性”、“目录” 选项卡和 “配置”，然后验证相应文件类型的脚本映射是否设置为允许所使用的谓词。
403.2	读访问被禁止。验证是否已将 IIS 设置为允许对目录进行读访问。另外，如果您正在使用默认文件，请验证该文件是否存在。
403.3	写访问被禁止。验证 IIS 权限和 NTFS 权限是否已设置以便向该目录授予写访问权。
403.4	要求 SSL。禁用要求安全通道选项，或使用 HTTPS 代替 HTTP 来访问该页面。
403.5	要求 SSL 128。禁用要求128位加密选项，或使用支持128位加密的浏览器以查看该页面。
403.6	IP 地址被拒绝。您已经将服务器配置为拒绝访问您当前的 IP 地址。
403.7	要求客户端证书。您已经将服务器配置为要求提供证书进行客户端身份验证，但是您没有安装有效的客户端证书。
403.8	站点访问被拒绝。您已经为用来访问服务器的域设置了域名限制。
403.9	用户数过多。与该服务器连接的用户数量超过了您设置的连接限制。注意：Microsoft Windows 2000 Professional 和 Windows XP Professional 自动设置了在 IIS 上最多10个连接的限制。您无法更改此限制。
403.10	配置无效。
403.11	密码更改。
403.12	拒绝访问映射表。您要访问的页面要求提供客户端证书。但是，映射到该客户端证书的用户 ID 已经拒绝访问该文件。
403.13	客户端证书被吊销。
403.14	拒绝目录列表。
403.15	超出客户端访问许可。
403.16	客户端证书不受信任或无效。
403.17	客户端证书已过期或尚未生效。
403.18	在当前的应用程序池中不能执行所请求的 URL。这个错误代码为 IIS 6.0 所专用。
403.19	不能为这个应用程序池中的客户端执行 CGI。这个错误代码为 IIS 6.0 所专用。
403.20	Passport 登录失败。这个错误代码为 IIS 6.0 所专用。

404 状态码
HTTP 状态码	说明
404.0	没有找到文件或目录。
404.1	无法通过请求的端口访问网站。此错误消息表明，试图访问的网站的 IP 地址不接受来自此请求所用端口的请求。
404.2	Web 服务扩展锁定策略阻止本请求。在 IIS 6.0 中，表示 Web 服务扩展列表中已经阻止了该请求。
404.3	MIME 映射策略阻止了此请求。 如果存在下列情况，将出现此问题：
未配置请求的文件扩展名的处理程序映射。
没有为网站或应用程序配置相应的 MIME 类型。
5xx：服务器错误
服务器由于遇到错误而不能完成该请求。

HTTP 状态码	说明
500	内部服务器错误。很多服务器端错误都可能导致此错误消息。事件查看器日志包含更详细的错误原因。此外，您可以禁用友好 HTTP 错误消息以便收到详细的错误说明。IIS 定义了几个不同的500错误，用于指示更为具体的错误原因，详见 500状态码。
501	页眉值指定了未实现的配置。
502	Web 服务器作为网关或代理服务器时，从上游服务器收到了无效响应。此类错误一般与服务器本身有关（与请求无关）。IIS 定义了几个不同的502错误，用于指示更为具体的错误原因，详见 502状态码。
503	目前服务器无法使用，一般是因为服务器超载或停止维护。
504	网关超时。
505	HTTP 版本不受支持。

500状态码
HTTP 状态码	说明
500.12	应用程序正忙于在 Web 服务器上重新启动。这表示您在 IIS 重新启动应用程序的过程中试图加载 ASP 页。刷新页面后，此消息即会消失。如果刷新页面后，此消息再次出现，可能是防病毒软件正在扫描 Global.asa 文件。
500.13	Web 服务器太忙。
500.15	不允许直接请求 Global.asa。
500.16	UNC 授权凭据不正确。这个错误代码为 IIS 6.0 所专用。
500.18	无法打开 URL 授权存储库。这个错误代码为 IIS 6.0 所专用。
500.19	此文件的数据在元数据库中配置不正确。如果 XML 元数据库在您尝试访问的内容类型中包含无效的配置信息，您就会收到此错误。要解决此问题，请删除或更正无效的配置。此问题通常表示 ScriptMap 元数据库键中存在问题。
500.100	内部 ASP 错误。 如果试图加载的 ASP 页中含有错误代码，将出现此错误消息。若要获得更确切的错误消息，请禁用友好 HTTP 错误消息。默认情况下，只会在默认网站上启用此错误消息。

502 状态码
HTTP 状态码	说明
502.1	CGI 应用程序超时。
502.2	CGI 应用程序出错。





**2.Ajax原理**

## 1.1 Ajax

、是什么
AJAX全称(Async Javascript and XML)

即异步的JavaScript 和XML，是一种创建交互式网页应用的网页开发技术，可以在不重新加载整个网页的情况下，与服务器交换数据，并且更新部分网页

Ajax的原理简单来说通过XmlHttpRequest对象来向服务器发异步请求，从服务器获得数据，然后用JavaScript来操作DOM而更新页面


实现 Ajax异步交互需要服务器逻辑进行配合，需要完成以下步骤：

创建 Ajax的核心对象 XMLHttpRequest对象

通过 XMLHttpRequest 对象的 open() 方法与服务端建立连接

构建请求所需的数据内容，并通过XMLHttpRequest 对象的 send() 方法发送给服务器端

通过 XMLHttpRequest 对象提供的 onreadystatechange 事件监听服务器端你的通信状态

接受并处理服务端向客户端响应的数据结果

将处理结果更新到 HTML页面中




3. 24.说⼀下如何对 axios 进⾏⼆次封装?以及 api 如何封装?(30%)

1. 在 src ⽂件夹内创建 utils ⽂件夹
2. 在 utils ⽂件夹内创建 request.js ⽂件
3. 在 request.js 内引⼊ axios
4. 使⽤ axios.create ⽅法创建 axios 的实例,在 axios.create ⽅法⾥⾯可以配置请求的公共地址和超时时间以及其他的⼀些配置
5. 在创建请求拦截器和响应拦截器
6. 在请求拦截器⾥⾯可以获取 vuex 的 token,并通过 config.header.token = vuex 的 token,将 token 发送给后台
7. 在请求拦截器⾥⾯我们配置 loading 加载
8. 在响应拦截器⾥⾯我们可以结束 loading 加载以及 token 的过期处理,以及错误响应信息的处理
9. 最后通过 export default 导出 axios 的实例对象
10. 在 src ⽂件内创建 api ⽂件夹
11. 在 api ⽂件夹内创建对应模块的 js ⽂件
12. 在对应的⽂件⾥⾯引⼊ request.js ⽂件
13. 封装 api ⽅法
14. 最后通过 export default 导出封装的 api ⽅法





4.跨域

为什么会出现跨域问题
出于浏览器的同源策略限制。同源策略（Sameoriginpolicy）是一种约定，它是浏览器最核心也最基本的安全功能，如果缺少了同源策略，则浏览器的正常功能可能都会受到影响。可以说Web是构建在同源策略基础之上的，浏览器只是针对同源策略的一种实现。同源策略会阻止一个域的javascript脚本和另外一个域的内容进行交互。所谓同源（即指在同一个域）就是两个页面具有相同的协议（protocol），主机（host）和端口号（port）

跨域解决方案
通过jsonp跨域
document.domain + iframe跨域
location.hash + iframe
window.name + iframe跨域
postMessage跨域
跨域资源共享（CORS）
nginx代理跨域
nodejs中间件代理跨域
WebSocket协议跨域





**5.promise**

什么是Promise
Promise 是异步编程的一种解决方案，其实是一个构造函数，自己身上有all、reject、resolve这几个方法，原型上有then、catch等方法。（ps:什么是原型：javascript中的原型与原型链_傻小胖的博客-CSDN博客_javascript原型和原型链）

Promise对象有以下两个特点。

（1）对象的状态不受外界影响。Promise对象代表一个异步操作，有三种状态：pending（进行中）、fulfilled（已成功）和rejected（已失败）。只有异步操作的结果，可以决定当前是哪一种状态，任何其他操作都无法改变这个状态。这也是Promise这个名字的由来，它的英语意思就是“承诺”，表示其他手段无法改变。

（2）一旦状态改变，就不会再变，任何时候都可以得到这个结果。Promise对象的状态改变，只有两种可能：从pending变为fulfilled和从pending变为rejected。只要这两种情况发生，状态就凝固了，不会再变了，会一直保持这个结果，这时就称为 resolved（已定型）。如果改变已经发生了，你再对Promise对象添加回调函数，也会立即得到这个结果。这与事件（Event）完全不同，事件的特点是，如果你错过了它，再去监听，是得不到结果的。

下面先 new一个Promise

let p = new Promise(function(resolve, reject){
		//做一些异步操作
		setTimeout(function(){
			console.log('执行完成Promise');
			resolve('要返回的数据可以任何数据例如接口返回数据');
		}, 2000);
	});
刷新页面会发现控制台直接打出



其执行过程是：执行了一个异步操作，也就是setTimeout，2秒后，输出“执行完成”，并且调用resolve方法。

注意！我只是new了一个对象，并没有调用它，我们传进去的函数就已经执行了，这是需要注意的一个细节。所以我们用Promise的时候一般是包在一个函数中，在需要的时候去运行这个函数，如：

<div onClick={promiseClick}>开始异步请求</div>

const promiseClick =()=>{
	 console.log('点击方法被调用')
	 let p = new Promise(function(resolve, reject){
		//做一些异步操作
		setTimeout(function(){
				console.log('执行完成Promise');
				resolve('要返回的数据可以任何数据例如接口返回数据');
			}, 2000);
		});
        return p
	}
刷新页面的时候是没有任何反映的，但是点击后控制台打出



当放在函数里面的时候只有调用的时候才会被执行

那么，接下里解决两个问题：

1、为什么要放在函数里面

2、resolve是个什么鬼

我们包装好的函数最后，会return出Promise对象，也就是说，执行这个函数我们得到了一个Promise对象。接下来就可以用Promise对象上有then、catch方法了，这就是Promise的强大之处了，看下面的代码：

promiseClick().then(function(data){
    console.log(data);
    //后面可以用传过来的数据做些其他操作
    //......
});
这样控制台输出



先是方法被调用起床执行了promise,最后执行了promise的then方法，then方法是一个函数接受一个参数是接受resolve返回的数据这事就输出了‘要返回的数据可以任何数据例如接口返回数据’

这时候你应该有所领悟了，原来then里面的函数就跟我们平时的回调函数一个意思，能够在promiseClick这个异步任务执行完成之后被执行。这就是Promise的作用了，简单来讲，就是能把原来的回调写法分离出来，在异步操作执行完后，用链式调用的方式执行回调函数。

你可能会觉得在这个和写一个回调函数没有什么区别；那么，如果有多层回调该怎么办？如果callback也是一个异步操作，而且执行完后也需要有相应的回调函数，该怎么办呢？总不能再定义一个callback2，然后给callback传进去吧。而Promise的优势在于，可以在then方法中继续写Promise对象并返回，然后继续调用then来进行回调操作。

所以：精髓在于：Promise只是能够简化层层回调的写法，而实质上，Promise的精髓是“状态”，用维护状态、传递状态的方式来使得回调函数能够及时调用，它比传递callback函数要简单、灵活的多。所以使用Promise的正确场景是这样的：

promiseClick()
.then(function(data){
    console.log(data);
    return runAsync2();
})
.then(function(data){
    console.log(data);
    return runAsync3();
})
.then(function(data){
    console.log(data);
});
这样能够按顺序，每隔两秒输出每个异步回调中的内容，在runAsync2中传给resolve的数据，能在接下来的then方法中拿到。



（Ps：此处执行多次是因为研究该用法的时候我在一个react的demo中进行的，该页面多个元素改变导致页面多次渲染执行所致，正常页面只渲染一次的话就所有只会执行一次）

reject的用法
以上是对promise的resolve用法进行了解释，相当于resolve是对promise成功时候的回调，它把promise的状态修改为

fullfiled，那么，reject就是失败的时候的回调，他把promise的状态修改为rejected，这样我们在then中就能捕捉到，然后执行“失败”情况的回调。

function promiseClick(){
		let p = new Promise(function(resolve, reject){
			setTimeout(function(){
				var num = Math.ceil(Math.random()*20); //生成1-10的随机数
				console.log('随机数生成的值：',num)
				if(num<=10){
					resolve(num);
				}
				else{
					reject('数字太于10了即将执行失败回调');
				}
			}, 2000);
		   })
		   return p
	   }

	promiseClick().then(
		function(data){
			console.log('resolved成功回调');
			console.log('成功回调接受的值：',data);
		}, 
		function(reason){
			console.log('rejected失败回调');
			console.log('失败执行回调抛出失败原因：',reason);
		}
	);	

执行结果：



（PS：此处也是执行多次所以输出多次，执行多次的原因和上次原因一致）

以上代码：调用promiseClick方法执行，2秒后获取到一个随机数，如果小于10，我们算成功，调用resolve修改Promise的状态为fullfiled。否则我们认为是“失败”了，调用reject并传递一个参数，作为失败的原因。并将状态改成rejected

运行promiseClick并且在then中传了两个参数，这两个参数分别是两个函数，then方法可以接受两个参数，第一个对应resolve的回调，第二个对应reject的回调。（也就是说then方法中接受两个回调，一个成功的回调函数，一个失败的回调函数，并且能在回调函数中拿到成功的数据和失败的原因），所以我们能够分别拿到成功和失败传过来的数据就有以上的运行结果

catch的用法
与Promise对象方法then方法并行的一个方法就是catch,与try  catch类似，catch就是用来捕获异常的，也就是和then方法中接受的第二参数rejected的回调是一样的，如下：

function promiseClick(){
		let p = new Promise(function(resolve, reject){
			setTimeout(function(){
				var num = Math.ceil(Math.random()*20); //生成1-10的随机数
				console.log('随机数生成的值：',num)
				if(num<=10){
					resolve(num);
				}
				else{
					reject('数字太于10了即将执行失败回调');
				}
			}, 2000);
		   })
		   return p
	   }

	promiseClick().then(
		function(data){
			console.log('resolved成功回调');
			console.log('成功回调接受的值：',data);
		}
	)
	.catch(function(reason, data){
		console.log('catch到rejected失败回调');
		console.log('catch失败执行回调抛出失败原因：',reason);
	});	

执行结果：

效果和写在then的第二个参数里面一样。它将大于10的情况下的失败回调的原因输出，但是，它还有另外一个作用：在执行resolve的回调（也就是上面then中的第一个参数）时，如果抛出异常了（代码出错了），那么并不会报错卡死js，而是会进到这个catch方法中。如下：

function promiseClick(){
		let p = new Promise(function(resolve, reject){
			setTimeout(function(){
				var num = Math.ceil(Math.random()*20); //生成1-10的随机数
				console.log('随机数生成的值：',num)
				if(num<=10){
					resolve(num);
				}
				else{
					reject('数字太于10了即将执行失败回调');
				}
			}, 2000);
		   })
		   return p
	   }

	promiseClick().then(
		function(data){
			console.log('resolved成功回调');
			console.log('成功回调接受的值：',data);
			console.log(noData);
		}
	)
	.catch(function(reason, data){
		console.log('catch到rejected失败回调');
		console.log('catch失败执行回调抛出失败原因：',reason);
	});	

执行结果：



在resolve的回调中，我们console.log(noData);而noData这个变量是没有被定义的。如果我们不用Promise，代码运行到这里就直接在控制台报错了，不往下运行了。但是在这里，会得到上图的结果，也就是说进到catch方法里面去了，而且把错误原因传到了reason参数中。即便是有错误的代码也不会报错了

all的用法
与then同级的另一个方法，all方法，该方法提供了并行执行异步操作的能力，并且在所有异步操作执行完后并且执行结果都是成功的时候才执行回调。

将上述方法复制两份并重命名promiseClick3(), promiseClick2(), promiseClick1()，如下

function promiseClick1(){
		let p = new Promise(function(resolve, reject){
			setTimeout(function(){
				var num = Math.ceil(Math.random()*20); //生成1-10的随机数
				console.log('随机数生成的值：',num)
				if(num<=10){
					resolve(num);
				}
				else{
					reject('数字太于10了即将执行失败回调');
				}
			}, 2000);
		   })
		   return p
	   }
	   function promiseClick2(){
		let p = new Promise(function(resolve, reject){
			setTimeout(function(){
				var num = Math.ceil(Math.random()*20); //生成1-10的随机数
				console.log('随机数生成的值：',num)
				if(num<=10){
					resolve(num);
				}
				else{
					reject('数字太于10了即将执行失败回调');
				}
			}, 2000);
		   })
		   return p
	   }
	   function promiseClick3(){
		let p = new Promise(function(resolve, reject){
			setTimeout(function(){
				var num = Math.ceil(Math.random()*20); //生成1-10的随机数
				console.log('随机数生成的值：',num)
				if(num<=10){
					resolve(num);
				}
				else{
					reject('数字太于10了即将执行失败回调');
				}
			}, 2000);
		   })
		   return p
	   }

	Promise
		.all([promiseClick3(), promiseClick2(), promiseClick1()])
		.then(function(results){
			console.log(results);
		});

Promise.all来执行，all接收一个数组参数，这组参数为需要执行异步操作的所有方法，里面的值最终都算返回Promise对象。这样，三个异步操作的并行执行的，等到它们都执行完后才会进到then里面。那么，三个异步操作返回的数据哪里去了呢？都在then里面，all会把所有异步操作的结果放进一个数组中传给then，然后再执行then方法的成功回调将结果接收，结果如下：（分别执行得到结果，all统一执行完三个函数并将值存在一个数组里面返回给then进行回调输出）：



这样以后就可以用all并行执行多个异步操作，并且在一个回调中处理所有的返回数据，比如你需要提前准备好所有数据才渲染页面的时候就可以使用all,执行多个异步操作将所有的数据处理好，再去渲染

race的用法
all是等所有的异步操作都执行完了再执行then方法，那么race方法就是相反的，谁先执行完成就先执行回调。先执行完的不管是进行了race的成功回调还是失败回调，其余的将不会再进入race的任何回调

我们将上面的方法延迟分别改成234秒


function promiseClick1(){
		let p = new Promise(function(resolve, reject){
			setTimeout(function(){
				var num = Math.ceil(Math.random()*20); //生成1-10的随机数
				console.log('2s随机数生成的值：',num)
				if(num<=10){
					resolve(num);
				}
				else{
					reject('2s数字太于10了即将执行失败回调');
				}
			}, 2000);
		   })
		   return p
	   }
	   function promiseClick2(){
		let p = new Promise(function(resolve, reject){
			setTimeout(function(){
				var num = Math.ceil(Math.random()*20); //生成1-10的随机数
				console.log('3s随机数生成的值：',num)
				if(num<=10){
					resolve(num);
				}
				else{
					reject('3s数字太于10了即将执行失败回调');
				}
			}, 3000);
		   })
		   return p
	   }
	   function promiseClick3(){
		let p = new Promise(function(resolve, reject){
			setTimeout(function(){
				var num = Math.ceil(Math.random()*20); //生成1-10的随机数
				console.log('4s随机数生成的值：',num)
				if(num<=10){
					resolve(num);
				}
				else{
					reject('4s数字太于10了即将执行失败回调');
				}
			}, 4000);
		   })
		   return p
	   }

	Promise
		.race([promiseClick3(), promiseClick2(), promiseClick1()])
		.then(function(results){
			console.log('成功',results);
		},function(reason){
			console.log('失败',reason);
		});

当2s后promiseClick1执行完成后就已经进入到了then里面回调，在then里面的回调开始执行时，promiseClick2()和promiseClick3()并没有停止，仍旧再执行。于是再过3秒后，输出了他们各自的值，但是将不会再进入race的任何回调。如图2s生成10进入race的成功回调后，其余函数继续执行，但是将不会再进入race的任何回调，2s生成16进入了race的失败回调，其余的继续执行，但是将不会再进入race的任何回调。



race的使用比如可以使用在一个请求在10s内请求成功的话就走then方法，如果10s内没有请求成功的话进入reject回调执行另一个操作。

补充：（由于有人问我怎么实现race的使用比如可以使用在一个请求在10s内请求成功的话就走then方法，如果10s内没有请求成功的话进入reject回调执行另一个操作。这个问题，想是我的表达有点问题，那我就举个例子）

 //请求某个table数据
    function requestTableList(){
        var p = new Promise((resolve, reject) => {
               //去后台请求数据，这里可以是ajax,可以是axios,可以是fetch 
                resolve(res);
        });
        return p;
    }
  //延时函数，用于给请求计时 10s
      function timeout(){
          var p = new Promise((resolve, reject) => {
              setTimeout(() => {
                  reject('请求超时');
              }, 10000);
          });
          return p;
      }
      Promise.race([requestTableList(), timeout()]).then((data) =>{
        //进行成功回调处理
        console.log(data);
      }).catch((err) => {
        // 失败回调处理
          console.log(err);
      });

